Workbook

Sheet Settings
A1: Progression Settings
A3: Progression % between matching cycles (M3 vs M1, M4 vs M2). Edit yellow cells to adjust targets.
A5: Category | B5: Min % Increase | C5: Max % Increase | D5: Mid % (used for target) | E5: Notes
A6: compound | B6: 0.05 | C6: 0.1 | D6: =AVERAGE(B6:C6) -> 0.075 | E6: Hex bar DL, bench, hip thrust, weighted pull-up. Smaller jumps - heavier loads.
A7: accessory | B7: 0.075 | C7: 0.125 | D7: =AVERAGE(B7:C7) -> 0.1 | E7: Rows, pressing variations, hinges. Moderate jumps.
A8: unilateral | B8: 0.075 | C8: 0.15 | D8: =AVERAGE(B8:C8) -> 0.1125 | E8: Split squats, step-ups, lunges. Single-leg can progress faster.
A9: power | B9: 0.05 | C9: 0.1 | D9: =AVERAGE(B9:C9) -> 0.075 | E9: Med ball, jumps. Progress mostly by intent/speed, load 2nd.
A10: conditioning | B10: 0.05 | C10: 0.1 | D10: =AVERAGE(B10:C10) -> 0.075 | E10: Rounds, intensity, or interval load. Manual adjustments expected.
A11: core | B11: 0.075 | C11: 0.15 | D11: =AVERAGE(B11:C11) -> 0.1125 | E11: Anti-rotation, anti-extension. Time under tension scales well.
A14: How to Use
A15: 1. Each training day has its own tab (M1D1 = Month 1 Day 1, etc.).
A16: 2. Yellow cells = your input (Actual Load, RPE, Notes).
A17: 3. Green cells = auto-calculated targets pulled from the matching prior cycle.
A18: 4. Month 3 days pull progression targets from Month 1 days (M1D1 -> M3D1, etc.).
A19: 5. Month 4 days pull progression targets from Month 2 days.
A20: 6. Adjust the progression % per category above to make targets more or less aggressive.
A21: 7. The Dashboard tab summarizes top-set actuals for key lifts across all 16 weeks.
A22: 8. 'TargetLoad_NextCycle' shows where the next cycle's prescription will land based on what was lifted.
A25: Color Legend
A26: Yellow | B26: Your input (Actual Load, RPE, Notes)
A27: Green | B27: Auto-calculated (target loads, progression %)
A28: Grey | B28: Reference info (sets, reps, prescribed load text)

Sheet M1D1
A1: Month 1 - Day 1 (Conditioning Emphasis - Full Body)
A2: Loading guidance: Wk1: RPE 5-6, technique loads | Wk2: +5-10%, RPE 6-7 | Wk3: +set or +5%, RPE 7 | Wk4: hold load, add reps, RPE 7-8
A3: WARMUP (8-10 min)
A4: Block A - Activation / Mobility (3-4 min)
A5: Drill | H5: Dose | K5: Cue
A6: 90/90 breathing on back, feet on bench | H6: 5 breaths | K6: Full exhale, ribs down, posterior pelvic tilt
A7: 90/90 hip switches | H7: 6 ea side | K7: Hip IR/ER - golf-specific
A8: Open book / thoracic windmill (side-lying) | H8: 6 ea | K8: T-rotation + R shoulder ER - golf critical
A9: Ankle rocks against wall | H9: 8 ea | K9: Dorsiflexion for PFP + squat patterning
A10: Block B - Dynamic Sequence (5-6 min, ~15-20 yd each, continuous flow)
A11: Movement | H11: Distance | K11: Focus
A12: Jog | H12: 20 yd down + back | K12: Easy aerobic primer
A13: Carioca | H13: 20 yd ea direction | K13: Hip rotation, frontal plane
A14: Walking lunge w/ rotation | H14: 8 reps | K14: Hip flexor + T-spine; PFP-aware depth
A15: Walking single-leg RDL | H15: 6 ea leg | K15: Posterior chain, balance
A16: Straight-leg kicks | H16: 8 ea leg | K16: Dynamic hamstring length
A17: Lateral lunges | H17: 6 ea side | K17: Adductor / frontal plane hip
A18: Side shuffles | H18: 15 yd ea x 2 | K18: Hip abductors, rotational prep
A19: Quick feet (ladder) | H19: 15-20 sec x 2 | K19: CNS prime, foot speed
A21: POWER PREP (~2 min)
A22: Same-pattern prep (M1) | Pairs with: A1. Med ball rotational throw
A23: Prep Movement | H23: Dose | K23: Cue
A24: Cable wood chop, slow (high-to-low) | H24: 1 x 6 ea side | K24: Tempo 3-1-1. Same plane, lower velocity. Primes rotation.
A28: MAIN WORKOUT
A29: Exercise | B29: Sets | C29: Reps | D29: Prescribed | E29: Wk 1 | G29: Wk 2 | I29: Wk 3 | K29: Wk 4 | M29: Notes | N29: Next-Cycle Target | P29: Category
E30: Load (lb) | F30: RPE | G30: Load (lb) | H30: RPE | I30: Load (lb) | J30: RPE | K30: Load (lb) | L30: RPE | N30: Min (lb) | O30: Max (lb)
A31: A1. Med ball rotational throw into wall | B31: 3 | C31: 6 ea side | D31: WT 10 lb | M31: Hips drive rotation, not arms. Golf-specific power primer. | N31: =IF(OR(NOT(ISNUMBER(K31)),K31=0),"",ROUND(K31*(1+Settings!$B$9),0)) | O31: =IF(OR(NOT(ISNUMBER(K31)),K31=0),"",ROUND(K31*(1+Settings!$C$9),0)) | P31: power
A32: A2. Hex bar deadlift | B32: 3 | C32: 8 | D32: WT 95 lb | M32: Hip hinge focus. Light handle, hips back, neutral spine. RPE 6-7 target - adjust if too easy/hard. | N32: =IF(OR(NOT(ISNUMBER(K32)),K32=0),"",ROUND(K32*(1+Settings!$B$6),0)) | O32: =IF(OR(NOT(ISNUMBER(K32)),K32=0),"",ROUND(K32*(1+Settings!$C$6),0)) | P32: compound
A33: B1. Half-kneeling barbell landmine press (alt arms) | B33: 3 | C33: 8 ea | D33: WT 10 lb | M33: Barbell in landmine adapter, plates on working end. Treat bar as 0. Neutral-ish grip, diagonal press path - R shoulder friendly. | N33: =IF(OR(NOT(ISNUMBER(K33)),K33=0),"",ROUND(K33*(1+Settings!$B$7),0)) | O33: =IF(OR(NOT(ISNUMBER(K33)),K33=0),"",ROUND(K33*(1+Settings!$C$7),0)) | P33: accessory
A34: B2. Goblet reverse lunge | B34: 3 | C34: 8 ea | D34: WT 26 lb KB | M34: Reverse - PFP friendly. Front shin near vertical. RPE 6 target. | N34: =IF(OR(NOT(ISNUMBER(K34)),K34=0),"",ROUND(K34*(1+Settings!$B$8),0)) | O34: =IF(OR(NOT(ISNUMBER(K34)),K34=0),"",ROUND(K34*(1+Settings!$C$8),0)) | P34: unilateral
A35: C. Conditioning circuit (3 rounds) | B35: 3 | C35: see notes | D35: KB swing 35 lb | M35: Bike 60s mod / KB swing x12 (35 lb) / side shuffle 20yd x2 / 60s rest. Build to 4 rounds by Wk 4. | N35: - | O35: - | P35: conditioning
A36: D. Pallof press, tall kneeling | B36: 3 | C36: 10 ea | D36: WT 20 lb cable | M36: Resist rotation, breathe out on press. | N36: =IF(OR(NOT(ISNUMBER(K36)),K36=0),"",ROUND(K36*(1+Settings!$B$11),0)) | O36: =IF(OR(NOT(ISNUMBER(K36)),K36=0),"",ROUND(K36*(1+Settings!$C$11),0)) | P36: core
A39: COOL DOWN (5 min)
A40: Drill | H40: Dose | K40: Purpose
A41: Nasal diaphragmatic breathing, supine | H41: 2 min | K41: Down-regulate after conditioning
A42: Half-kneeling adductor rock-back | H42: 8 reps ea | K42: Hip recovery
A43: Foam roll T-spine extensions | H43: 8 reps | K43: Decompress thoracic, reset posture

Sheet M1D2
A1: Month 1 - Day 2 (Strength Emphasis - Full Body)
A2: Loading guidance: Wk1: RPE 5-6 | Wk2: +5-10% | Wk3: +set/+5%, RPE 7 | Wk4: RPE 7-8, test week
A3: WARMUP (8-10 min)
A4: Block A - Activation / Mobility (3-4 min)
A5: Drill | H5: Dose | K5: Cue
A6: 90/90 breathing on back, feet on bench | H6: 5 breaths | K6: Full exhale, ribs down, posterior pelvic tilt
A7: Glute bridge with 2-sec hold | H7: 10 reps | K7: Glute activation, ribs down at top
A8: Ankle rocks against wall | H8: 8 ea | K8: Dorsiflexion for PFP + squat patterning
A9: Bird dog with elbow-to-knee | H9: 6 ea | K9: Anti-extension + anti-rotation
A10: Block B - Dynamic Sequence (5-6 min, ~15-20 yd each, continuous flow)
A11: Movement | H11: Distance | K11: Focus
A12: Jog | H12: 20 yd down + back | K12: Easy aerobic primer
A13: Carioca | H13: 20 yd ea direction | K13: Hip rotation, frontal plane
A14: Walking lunge w/ rotation | H14: 8 reps | K14: Hip flexor + T-spine; PFP-aware depth
A15: Walking single-leg RDL | H15: 6 ea leg | K15: Posterior chain, balance
A16: Straight-leg kicks | H16: 8 ea leg | K16: Dynamic hamstring length
A17: Lateral lunges | H17: 6 ea side | K17: Adductor / frontal plane hip
A18: Side shuffles | H18: 15 yd ea x 2 | K18: Hip abductors, rotational prep
A19: Quick feet (ladder) | H19: 15-20 sec x 2 | K19: CNS prime, foot speed
A21: POWER PREP (~2 min)
A22: No explosive movements today - skip prep, proceed to Main Workout.
A28: MAIN WORKOUT
A29: Exercise | B29: Sets | C29: Reps | D29: Prescribed | E29: Wk 1 | G29: Wk 2 | I29: Wk 3 | K29: Wk 4 | M29: Notes | N29: Next-Cycle Target | P29: Category
E30: Load (lb) | F30: RPE | G30: Load (lb) | H30: RPE | I30: Load (lb) | J30: RPE | K30: Load (lb) | L30: RPE | N30: Min (lb) | O30: Max (lb)
A31: A. Hex bar deadlift | B31: 4 | C31: 5 | D31: WT 135 lb | E31: 135 | F31: 5 | M31: Primary strength lift. Reset every rep early on. Build to RPE 7 by Wk 4. | N31: =IF(OR(NOT(ISNUMBER(K31)),K31=0),"",ROUND(K31*(1+Settings!$B$6),0)) | O31: =IF(OR(NOT(ISNUMBER(K31)),K31=0),"",ROUND(K31*(1+Settings!$C$6),0)) | P31: compound
A32: B1. DB floor press (neutral grip) | B32: 4 | C32: 6-8 | D32: WT 35 lb ea DB | M32: Floor limits ROM - protects R shoulder. Move to bench Wk3 if pain-free. RPE 7 target. | N32: =IF(OR(NOT(ISNUMBER(K32)),K32=0),"",ROUND(K32*(1+Settings!$B$6),0)) | O32: =IF(OR(NOT(ISNUMBER(K32)),K32=0),"",ROUND(K32*(1+Settings!$C$6),0)) | P32: compound
A33: B2. TRX row, feet forward | B33: 4 | C33: 10 | D33: BW (foot angle) | M33: Retract scaps first, no shrug. Progress by walking feet forward. | N33: - | O33: - | P33: accessory
A34: C1. Bulgarian split squat | B34: 3 | C34: 8 ea | D34: WT 25 lb ea DB | M34: Hip-dominant lean. Stop at pain-free depth for PFP. RPE 7 target. | N34: =IF(OR(NOT(ISNUMBER(K34)),K34=0),"",ROUND(K34*(1+Settings!$B$8),0)) | O34: =IF(OR(NOT(ISNUMBER(K34)),K34=0),"",ROUND(K34*(1+Settings!$C$8),0)) | P34: unilateral
A35: C2. 1-arm KB suitcase carry | B35: 3 | C35: 30 yd ea | D35: WT 53 lb KB | M35: Anti-lateral flexion. No leaning. Slow steps. Progress to 62 lb when controlled. | N35: =IF(OR(NOT(ISNUMBER(K35)),K35=0),"",ROUND(K35*(1+Settings!$B$8),0)) | O35: =IF(OR(NOT(ISNUMBER(K35)),K35=0),"",ROUND(K35*(1+Settings!$C$8),0)) | P35: unilateral
A36: D. Glute-ham iso back extension hold | B36: 3 | C36: 20-30 sec | D36: BW | M36: Posterior chain endurance. No hyperextension at top. Add 5-10 lb plate at chest when 30 sec is easy. | N36: - | O36: - | P36: core
A39: COOL DOWN (5 min)
A40: Drill | H40: Dose | K40: Purpose
A41: Couch stretch | H41: 45 sec ea side | K41: Hip flexor recovery after hinging + lunging
A42: Doorway pec stretch at 90/90 | H42: 30 sec ea | K42: Counter pressing posture (mindful R shoulder)
A43: 90/90 hip stretch hold | H43: 45 sec ea | K43: Hip rotation reset

Sheet M1D3
A1: Month 1 - Day 3 (Conditioning Emphasis - Full Body)
A2: Loading guidance: Same progression model as Day 1
A3: WARMUP (8-10 min)
A4: Block A - Activation / Mobility (3-4 min)
A5: Drill | H5: Dose | K5: Cue
A6: 90/90 breathing on back, feet on bench | H6: 5 breaths | K6: Full exhale, ribs down, posterior pelvic tilt
A7: 90/90 hip switches | H7: 6 ea side | K7: Hip IR/ER - golf-specific
A8: Wall slides, palms forward | H8: 8 reps | K8: Scap upward rotation, no forced flexion
A9: Mini-band monster walk (forward and back) | H9: 10 steps | K9: Glute med activation
A10: Block B - Dynamic Sequence (5-6 min, ~15-20 yd each, continuous flow)
A11: Movement | H11: Distance | K11: Focus
A12: Jog | H12: 20 yd down + back | K12: Easy aerobic primer
A13: Carioca | H13: 20 yd ea direction | K13: Hip rotation, frontal plane
A14: Walking lunge w/ rotation | H14: 8 reps | K14: Hip flexor + T-spine; PFP-aware depth
A15: Walking single-leg RDL | H15: 6 ea leg | K15: Posterior chain, balance
A16: Straight-leg kicks | H16: 8 ea leg | K16: Dynamic hamstring length
A17: Lateral lunges | H17: 6 ea side | K17: Adductor / frontal plane hip
A18: Side shuffles | H18: 15 yd ea x 2 | K18: Hip abductors, rotational prep
A19: Quick feet (ladder) | H19: 15-20 sec x 2 | K19: CNS prime, foot speed
A21: POWER PREP (~2 min)
A22: Same-pattern prep (M1) | Pairs with: A1. Med ball chest pass
A23: Prep Movement | H23: Dose | K23: Cue
A24: Wall ball, slow tempo (10 lb) | H24: 1 x 6 | K24: Squat-to-press at controlled speed. Same pattern, lower output.
A28: MAIN WORKOUT
A29: Exercise | B29: Sets | C29: Reps | D29: Prescribed | E29: Wk 1 | G29: Wk 2 | I29: Wk 3 | K29: Wk 4 | M29: Notes | N29: Next-Cycle Target | P29: Category
E30: Load (lb) | F30: RPE | G30: Load (lb) | H30: RPE | I30: Load (lb) | J30: RPE | K30: Load (lb) | L30: RPE | N30: Min (lb) | O30: Max (lb)
A31: A1. Med ball chest pass into wall | B31: 3 | C31: 8 | D31: WT 10 lb | E31: 14 | F31: 6 | M31: Triple extension if standing; controlled if seated. | N31: =IF(OR(NOT(ISNUMBER(K31)),K31=0),"",ROUND(K31*(1+Settings!$B$9),0)) | O31: =IF(OR(NOT(ISNUMBER(K31)),K31=0),"",ROUND(K31*(1+Settings!$C$9),0)) | P31: power
A32: A2. Goblet squat to box (12-20" box) | B32: 3 | C32: 8 | D32: WT 34 lb KB | E32: 34 | F32: 6 | M32: Box gives PFP-safe depth target. Hips back to box, drive through midfoot. RPE 6-7. | N32: =IF(OR(NOT(ISNUMBER(K32)),K32=0),"",ROUND(K32*(1+Settings!$B$7),0)) | O32: =IF(OR(NOT(ISNUMBER(K32)),K32=0),"",ROUND(K32*(1+Settings!$C$7),0)) | P32: accessory
A33: B1. Standing 1-arm cable row | B33: 3 | C33: 10 ea | D33: WT 30 lb cable | E33: 50 | F33: 6 | M33: Anti-rotation through trunk. | N33: =IF(OR(NOT(ISNUMBER(K33)),K33=0),"",ROUND(K33*(1+Settings!$B$7),0)) | O33: =IF(OR(NOT(ISNUMBER(K33)),K33=0),"",ROUND(K33*(1+Settings!$C$7),0)) | P33: accessory
A34: B2. Step-up to 12" box | B34: 3 | C34: 8 ea | D34: WT 25 lb ea DB | E34: 25 | F34: 7 | M34: Drive through heel of top foot, no push-off from bottom. | N34: =IF(OR(NOT(ISNUMBER(K34)),K34=0),"",ROUND(K34*(1+Settings!$B$8),0)) | O34: =IF(OR(NOT(ISNUMBER(K34)),K34=0),"",ROUND(K34*(1+Settings!$C$8),0)) | P34: unilateral
A35: C. Cardio intervals - Lateral-X Octane | B35: 1 | C35: 5 x 60s on/60s easy | D35: Mod resistance | M35: Frontal plane work. HR ~75-80% max if monitored. Track avg watts/resistance level. | N35: - | O35: - | P35: conditioning
A36: D. Side plank w/ top leg abduction | B36: 3 | C36: 8 ea side | D36: BW | F36: 6 | M36: Anti-lateral flexion + glute med. Add 4 lb ankle wt to top leg if BW gets easy. | N36: - | O36: - | P36: core
A39: COOL DOWN (5 min)
A40: Drill | H40: Dose | K40: Purpose
A41: Nasal diaphragmatic breathing, supine | H41: 2 min | K41: HR + parasympathetic recovery
A42: Standing forward fold, soft knees | H42: 45 sec | K42: Posterior chain decompression
A43: Child's pose with side reach | H43: 30 sec ea | K43: Lat + T-spine

Sheet M1D4
A1: Month 1 - Day 4 (Strength Emphasis - Full Body)
A2: Loading guidance: Same as Day 2
A3: WARMUP (8-10 min)
A4: Block A - Activation / Mobility (3-4 min)
A5: Drill | H5: Dose | K5: Cue
A6: 90/90 breathing on back, feet on bench | H6: 5 breaths | K6: Full exhale, ribs down, posterior pelvic tilt
A7: Open book / thoracic windmill (side-lying) | H7: 6 ea | K7: T-rotation + R shoulder ER - golf critical
A8: Standing band shoulder ER at 0 deg abd | H8: 10 ea | K8: Cuff activation - critical for R shoulder
A9: Bird dog with elbow-to-knee | H9: 6 ea | K9: Anti-extension + anti-rotation
A10: Block B - Dynamic Sequence (5-6 min, ~15-20 yd each, continuous flow)
A11: Movement | H11: Distance | K11: Focus
A12: Jog | H12: 20 yd down + back | K12: Easy aerobic primer
A13: Carioca | H13: 20 yd ea direction | K13: Hip rotation, frontal plane
A14: Walking lunge w/ rotation | H14: 8 reps | K14: Hip flexor + T-spine; PFP-aware depth
A15: Walking single-leg RDL | H15: 6 ea leg | K15: Posterior chain, balance
A16: Straight-leg kicks | H16: 8 ea leg | K16: Dynamic hamstring length
A17: Lateral lunges | H17: 6 ea side | K17: Adductor / frontal plane hip
A18: Side shuffles | H18: 15 yd ea x 2 | K18: Hip abductors, rotational prep
A19: Quick feet (ladder) | H19: 15-20 sec x 2 | K19: CNS prime, foot speed
A21: POWER PREP (~2 min)
A22: No explosive movements today - skip prep, proceed to Main Workout.
A28: MAIN WORKOUT
A29: Exercise | B29: Sets | C29: Reps | D29: Prescribed | E29: Wk 1 | G29: Wk 2 | I29: Wk 3 | K29: Wk 4 | M29: Notes | N29: Next-Cycle Target | P29: Category
E30: Load (lb) | F30: RPE | G30: Load (lb) | H30: RPE | I30: Load (lb) | J30: RPE | K30: Load (lb) | L30: RPE | N30: Min (lb) | O30: Max (lb)
A31: A. Hex bar Romanian deadlift | B31: 4 | C31: 6 | D31: WT 115 lb | M31: Hinge variant. Soft knee, hips back. RPE 7 target. | N31: =IF(OR(NOT(ISNUMBER(K31)),K31=0),"",ROUND(K31*(1+Settings!$B$6),0)) | O31: =IF(OR(NOT(ISNUMBER(K31)),K31=0),"",ROUND(K31*(1+Settings!$C$6),0)) | P31: compound
A32: B1. Half-kneeling 1-arm DB press (neutral) | B32: 4 | C32: 6-8 ea | D32: WT 25 lb DB | M32: R shoulder gets unilateral attention. Don't force ROM. RPE 7 target. R side may need lighter than L. | N32: =IF(OR(NOT(ISNUMBER(K32)),K32=0),"",ROUND(K32*(1+Settings!$B$7),0)) | O32: =IF(OR(NOT(ISNUMBER(K32)),K32=0),"",ROUND(K32*(1+Settings!$C$7),0)) | P32: accessory
A33: B2. Chest-supported DB row | B33: 4 | C33: 8 | D33: WT 35 lb ea DB | M33: Bench at 30 deg. Pull elbow to hip. RPE 7 target. | N33: =IF(OR(NOT(ISNUMBER(K33)),K33=0),"",ROUND(K33*(1+Settings!$B$7),0)) | O33: =IF(OR(NOT(ISNUMBER(K33)),K33=0),"",ROUND(K33*(1+Settings!$C$7),0)) | P33: accessory
A34: C1. KB front-rack reverse lunge | B34: 3 | C34: 8 ea | D34: WT 26 lb ea KB | M34: Posture demand on trunk. Single 34 lb KB goblet if double-rack uncomfortable. | N34: =IF(OR(NOT(ISNUMBER(K34)),K34=0),"",ROUND(K34*(1+Settings!$B$8),0)) | O34: =IF(OR(NOT(ISNUMBER(K34)),K34=0),"",ROUND(K34*(1+Settings!$C$8),0)) | P34: unilateral
A35: C2. Pallof press, half-kneeling | B35: 3 | C35: 8 ea side | D35: WT 20 lb cable | M35: 5-sec hold at end range. | N35: =IF(OR(NOT(ISNUMBER(K35)),K35=0),"",ROUND(K35*(1+Settings!$B$11),0)) | O35: =IF(OR(NOT(ISNUMBER(K35)),K35=0),"",ROUND(K35*(1+Settings!$C$11),0)) | P35: core
A36: D. Hollow body + dead bug ladder | B36: 3 | C36: 30s + 6 dead bugs | D36: BW | M36: Anti-extension. Scale to bent-knee if back aggravates. | N36: - | O36: - | P36: core
A39: COOL DOWN (5 min)
A40: Drill | H40: Dose | K40: Purpose
A41: Couch stretch | H41: 45 sec ea side | K41: Hip flexor recovery
A42: Open book stretch hold (3 breaths each side) | H42: 3 ea | K42: Final R shoulder ER + T-spine work
A43: Foam roll T-spine extensions | H43: 8 reps | K43: Decompress

Sheet M2D1
A1: Month 2 - Day 1 (Upper Body - Push Biased)
A2: Loading guidance: Wk5: RPE 7 | Wk6: +set or +5% | Wk7: RPE 8 top set, drop sets | Wk8: DELOAD -30 to -40% volume
A3: WARMUP (8-10 min)
A4: Block A - Activation / Mobility (3-4 min)
A5: Drill | H5: Dose | K5: Cue
A6: 90/90 breathing on back, feet on bench | H6: 5 breaths | K6: Full exhale, ribs down, posterior pelvic tilt
A7: Open book / thoracic windmill (side-lying) | H7: 6 ea | K7: T-rotation + R shoulder ER - golf critical
A8: Standing band shoulder ER at 0 deg abd | H8: 10 ea | K8: Cuff activation - critical for R shoulder
A9: Wall slides, palms forward | H9: 8 reps | K9: Scap upward rotation, no forced flexion
A10: Block B - Dynamic Sequence (5-6 min, ~15-20 yd each, continuous flow)
A11: Movement | H11: Distance | K11: Focus
A12: Jog | H12: 20 yd down + back | K12: Easy aerobic primer
A13: Carioca | H13: 20 yd ea direction | K13: Hip rotation, frontal plane
A14: Walking lunge w/ rotation | H14: 8 reps | K14: Hip flexor + T-spine; PFP-aware depth
A15: Walking single-leg RDL | H15: 6 ea leg | K15: Posterior chain, balance
A16: Straight-leg kicks | H16: 8 ea leg | K16: Dynamic hamstring length
A17: Lateral lunges | H17: 6 ea side | K17: Adductor / frontal plane hip
A18: Side shuffles | H18: 15 yd ea x 2 | K18: Hip abductors, rotational prep
A19: Quick feet (ladder) | H19: 15-20 sec x 2 | K19: CNS prime, foot speed
A21: POWER PREP (~2 min)
A22: Antagonist/contrast prep (M2) | Pairs with: A. Med ball overhead slam
A23: Prep Movement | H23: Dose | K23: Cue
A24: Lat pulldown iso-hold | H24: 1 x 5 reps, 5s hold ea | K24: Hold mid-range, release. Antagonist primes pulling pattern - explosive slam follows. PAP setup.
A28: MAIN WORKOUT
A29: Exercise | B29: Sets | C29: Reps | D29: Prescribed | E29: Wk 5 | G29: Wk 6 | I29: Wk 7 | K29: Wk 8 | M29: Notes | N29: Next-Cycle Target | P29: Category
E30: Load (lb) | F30: RPE | G30: Load (lb) | H30: RPE | I30: Load (lb) | J30: RPE | K30: Load (lb) | L30: RPE | N30: Min (lb) | O30: Max (lb)
A31: A. Med ball overhead slam (controlled) | B31: 3 | C31: 6 | D31: WT 10 lb | M31: Sub rotational scoop if shoulder flexion limits. | N31: =IF(OR(NOT(ISNUMBER(K31)),K31=0),"",ROUND(K31*(1+Settings!$B$9),0)) | O31: =IF(OR(NOT(ISNUMBER(K31)),K31=0),"",ROUND(K31*(1+Settings!$C$9),0)) | P31: power
A32: B. DB floor press or bench press | B32: 4 | C32: 8, 8, 6, 6 | D32: WT 45 lb ea DB | M32: Move to bench Wk6+ if Wk5 floor was clean. RPE 7-8 target. | N32: =IF(OR(NOT(ISNUMBER(K32)),K32=0),"",ROUND(K32*(1+Settings!$B$6),0)) | O32: =IF(OR(NOT(ISNUMBER(K32)),K32=0),"",ROUND(K32*(1+Settings!$C$6),0)) | P32: compound
A33: C. Standing barbell landmine press (1-arm) | B33: 3 | C33: 8 ea | D33: WT 25 lb | M33: Barbell in landmine, plates on working end. Best long-term overhead sub for R TSA. Start lighter on R side if needed. | N33: =IF(OR(NOT(ISNUMBER(K33)),K33=0),"",ROUND(K33*(1+Settings!$B$7),0)) | O33: =IF(OR(NOT(ISNUMBER(K33)),K33=0),"",ROUND(K33*(1+Settings!$C$7),0)) | P33: accessory
A34: D1. Chest-supported DB row | B34: 3 | C34: 10 | D34: WT 45 lb ea DB | M34: Heavy. 1-sec squeeze at top. RPE 8 target. | N34: =IF(OR(NOT(ISNUMBER(K34)),K34=0),"",ROUND(K34*(1+Settings!$B$7),0)) | O34: =IF(OR(NOT(ISNUMBER(K34)),K34=0),"",ROUND(K34*(1+Settings!$C$7),0)) | P34: accessory
A35: D2. TRX face pull | B35: 3 | C35: 12 | D35: BW (foot angle) | M35: ER + upper back. Critical for R shoulder posture. | N35: - | O35: - | P35: accessory
A36: E1. Cable triceps push-down | B36: 3 | C36: 12 | D36: WT 40 lb cable | N36: =IF(OR(NOT(ISNUMBER(K36)),K36=0),"",ROUND(K36*(1+Settings!$B$7),0)) | O36: =IF(OR(NOT(ISNUMBER(K36)),K36=0),"",ROUND(K36*(1+Settings!$C$7),0)) | P36: accessory
A37: E2. DB hammer curl | B37: 3 | C37: 10 | D37: WT 25 lb ea DB | M37: Neutral grip - wrist/elbow friendly. | N37: =IF(OR(NOT(ISNUMBER(K37)),K37=0),"",ROUND(K37*(1+Settings!$B$7),0)) | O37: =IF(OR(NOT(ISNUMBER(K37)),K37=0),"",ROUND(K37*(1+Settings!$C$7),0)) | P37: accessory
A38: F. Hanging knee raise or dead bug | B38: 3 | C38: 10 | D38: BW | M38: Anti-extension finisher. Add 2-4 lb ankle wt to dead bug version when easy. | N38: - | O38: - | P38: core
A41: COOL DOWN (5 min)
A42: Drill | H42: Dose | K42: Purpose
A43: Doorway pec stretch at 90/90 | H43: 30 sec ea | K43: Counter pressing volume (mindful R shoulder)
A44: Banded shoulder distraction (light) | H44: 30 sec ea | K44: Decompress R shoulder
A45: Foam roll T-spine extensions | H45: 8 reps | K45: Posture reset

Sheet M2D2
A1: Month 2 - Day 2 (Lower Body - Strength Biased)
A2: Loading guidance: Wk5: RPE 7 | Wk6: +set or +5% | Wk7: RPE 8 top set | Wk8: DELOAD
A3: WARMUP (8-10 min)
A4: Block A - Activation / Mobility (3-4 min)
A5: Drill | H5: Dose | K5: Cue
A6: 90/90 breathing on back, feet on bench | H6: 5 breaths | K6: Full exhale, ribs down, posterior pelvic tilt
A7: Glute bridge with 2-sec hold | H7: 10 reps | K7: Glute activation, ribs down at top
A8: Ankle rocks against wall | H8: 8 ea | K8: Dorsiflexion for PFP + squat patterning
A9: 90/90 hip switches | H9: 6 ea side | K9: Hip IR/ER - golf-specific
A10: Block B - Dynamic Sequence (5-6 min, ~15-20 yd each, continuous flow)
A11: Movement | H11: Distance | K11: Focus
A12: Jog | H12: 20 yd down + back | K12: Easy aerobic primer
A13: Carioca | H13: 20 yd ea direction | K13: Hip rotation, frontal plane
A14: Walking lunge w/ rotation | H14: 8 reps | K14: Hip flexor + T-spine; PFP-aware depth
A15: Walking single-leg RDL | H15: 6 ea leg | K15: Posterior chain, balance
A16: Straight-leg kicks | H16: 8 ea leg | K16: Dynamic hamstring length
A17: Lateral lunges | H17: 6 ea side | K17: Adductor / frontal plane hip
A18: Side shuffles | H18: 15 yd ea x 2 | K18: Hip abductors, rotational prep
A19: Quick feet (ladder) | H19: 15-20 sec x 2 | K19: CNS prime, foot speed
A21: POWER PREP (~2 min)
A22: No explosive movements today - skip prep, proceed to Main Workout.
A28: MAIN WORKOUT
A29: Exercise | B29: Sets | C29: Reps | D29: Prescribed | E29: Wk 5 | G29: Wk 6 | I29: Wk 7 | K29: Wk 8 | M29: Notes | N29: Next-Cycle Target | P29: Category
E30: Load (lb) | F30: RPE | G30: Load (lb) | H30: RPE | I30: Load (lb) | J30: RPE | K30: Load (lb) | L30: RPE | N30: Min (lb) | O30: Max (lb)
A31: A. Hex bar deadlift | B31: 5 | C31: 5, 5, 3, 3, 3 | D31: WT 165 lb top | M31: Heaviest pulls of the week. Build top set to RPE 7-8. First 2 sets at ~85% of top. | N31: =IF(OR(NOT(ISNUMBER(K31)),K31=0),"",ROUND(K31*(1+Settings!$B$6),0)) | O31: =IF(OR(NOT(ISNUMBER(K31)),K31=0),"",ROUND(K31*(1+Settings!$C$6),0)) | P31: compound
A32: B. Bulgarian split squat | B32: 4 | C32: 8 ea | D32: WT 35 lb ea DB | M32: PFP-aware depth. Add heel lift if needed. RPE 8 target. | N32: =IF(OR(NOT(ISNUMBER(K32)),K32=0),"",ROUND(K32*(1+Settings!$B$8),0)) | O32: =IF(OR(NOT(ISNUMBER(K32)),K32=0),"",ROUND(K32*(1+Settings!$C$8),0)) | P32: unilateral
A33: C. Hip thrust (DB on hips, bench) | B33: 4 | C33: 10 | D33: WT 70 lb DB | M33: Pause 1 sec at top. Ribs down at lockout. RPE 8 target. Use heaviest single DB (up to 125 lb). | N33: =IF(OR(NOT(ISNUMBER(K33)),K33=0),"",ROUND(K33*(1+Settings!$B$6),0)) | O33: =IF(OR(NOT(ISNUMBER(K33)),K33=0),"",ROUND(K33*(1+Settings!$C$6),0)) | P33: compound
A34: D. Glute-ham Nordic eccentric (assisted) | B34: 3 | C34: 4-5 | D34: BW | M34: Catch with hands, push back up. Slowest descent possible - progress by descent tempo, not load. | N34: - | O34: - | P34: accessory
A35: E. Single-leg calf raise off step | B35: 3 | C35: 15 ea | D35: WT 25 lb DB | M35: Tib post + PFP support. | N35: =IF(OR(NOT(ISNUMBER(K35)),K35=0),"",ROUND(K35*(1+Settings!$B$8),0)) | O35: =IF(OR(NOT(ISNUMBER(K35)),K35=0),"",ROUND(K35*(1+Settings!$C$8),0)) | P35: unilateral
A36: F. Standing Pallof hold + rotation tap | B36: 3 | C36: 8 ea side | D36: WT 30 lb cable | M36: Trunk anti-rotation under fatigue. | N36: =IF(OR(NOT(ISNUMBER(K36)),K36=0),"",ROUND(K36*(1+Settings!$B$11),0)) | O36: =IF(OR(NOT(ISNUMBER(K36)),K36=0),"",ROUND(K36*(1+Settings!$C$11),0)) | P36: core
A39: COOL DOWN (5 min)
A40: Drill | H40: Dose | K40: Purpose
A41: Couch stretch | H41: 45 sec ea side | K41: Heavy hinge + split squat hip flexor decomp
A42: 90/90 hip stretch | H42: 45 sec ea | K42: Hip rotation
A43: Standing forward fold, soft knees | H43: 45 sec | K43: Posterior chain

Sheet M2D3
A1: Month 2 - Day 3 (Upper Body - Pull Biased)
A2: Loading guidance: Same as Day 1
A3: WARMUP (8-10 min)
A4: Block A - Activation / Mobility (3-4 min)
A5: Drill | H5: Dose | K5: Cue
A6: 90/90 breathing on back, feet on bench | H6: 5 breaths | K6: Full exhale, ribs down, posterior pelvic tilt
A7: Scapular push-up | H7: 8 reps | K7: Protraction/retraction without elbow bend
A8: Wall slides, palms forward | H8: 8 reps | K8: Scap upward rotation, no forced flexion
A9: Open book / thoracic windmill (side-lying) | H9: 6 ea | K9: T-rotation + R shoulder ER - golf critical
A10: Block B - Dynamic Sequence (5-6 min, ~15-20 yd each, continuous flow)
A11: Movement | H11: Distance | K11: Focus
A12: Jog | H12: 20 yd down + back | K12: Easy aerobic primer
A13: Carioca | H13: 20 yd ea direction | K13: Hip rotation, frontal plane
A14: Walking lunge w/ rotation | H14: 8 reps | K14: Hip flexor + T-spine; PFP-aware depth
A15: Walking single-leg RDL | H15: 6 ea leg | K15: Posterior chain, balance
A16: Straight-leg kicks | H16: 8 ea leg | K16: Dynamic hamstring length
A17: Lateral lunges | H17: 6 ea side | K17: Adductor / frontal plane hip
A18: Side shuffles | H18: 15 yd ea x 2 | K18: Hip abductors, rotational prep
A19: Quick feet (ladder) | H19: 15-20 sec x 2 | K19: CNS prime, foot speed
A21: POWER PREP (~2 min)
A22: No explosive movements today - skip prep, proceed to Main Workout.
A28: MAIN WORKOUT
A29: Exercise | B29: Sets | C29: Reps | D29: Prescribed | E29: Wk 5 | G29: Wk 6 | I29: Wk 7 | K29: Wk 8 | M29: Notes | N29: Next-Cycle Target | P29: Category
E30: Load (lb) | F30: RPE | G30: Load (lb) | H30: RPE | I30: Load (lb) | J30: RPE | K30: Load (lb) | L30: RPE | N30: Min (lb) | O30: Max (lb)
A31: A. Pull-up (band assist) or neutral-grip pulldown | B31: 4 | C31: 6-8 | D31: WT 90 lb pulldown | M31: Neutral grip best for R shoulder. RPE 7 target. If pull-up: track band thickness/reps unassisted. | N31: =IF(OR(NOT(ISNUMBER(K31)),K31=0),"",ROUND(K31*(1+Settings!$B$6),0)) | O31: =IF(OR(NOT(ISNUMBER(K31)),K31=0),"",ROUND(K31*(1+Settings!$C$6),0)) | P31: compound
A32: B. 1-arm DB row, bench-supported | B32: 4 | C32: 10 ea | D32: WT 55 lb DB | M32: Heavy. Pull to hip. RPE 8 target. | N32: =IF(OR(NOT(ISNUMBER(K32)),K32=0),"",ROUND(K32*(1+Settings!$B$7),0)) | O32: =IF(OR(NOT(ISNUMBER(K32)),K32=0),"",ROUND(K32*(1+Settings!$C$7),0)) | P32: accessory
A33: C. Landmine row or seated cable row | B33: 3 | C33: 10 | D33: WT 60 lb cable | M33: Barbell in landmine for row, or seated cable. Either works. | N33: =IF(OR(NOT(ISNUMBER(K33)),K33=0),"",ROUND(K33*(1+Settings!$B$7),0)) | O33: =IF(OR(NOT(ISNUMBER(K33)),K33=0),"",ROUND(K33*(1+Settings!$C$7),0)) | P33: accessory
A34: D1. Incline DB press (~20 deg, neutral) | B34: 3 | C34: 10 | D34: WT 35 lb ea DB | M34: Low incline protects R shoulder. RPE 7 target. | N34: =IF(OR(NOT(ISNUMBER(K34)),K34=0),"",ROUND(K34*(1+Settings!$B$7),0)) | O34: =IF(OR(NOT(ISNUMBER(K34)),K34=0),"",ROUND(K34*(1+Settings!$C$7),0)) | P34: accessory
A35: D2. TRX Y raise (scap-driven) | B35: 3 | C35: 10 | D35: BW (foot angle) | M35: Lower traps. Tiny range first if shoulder flexion limits. | N35: - | O35: - | P35: accessory
A36: E1. Cable face pull + ER | B36: 3 | C36: 12 | D36: WT 30 lb cable | M36: Cuff + rear delt - non-negotiable. | N36: =IF(OR(NOT(ISNUMBER(K36)),K36=0),"",ROUND(K36*(1+Settings!$B$7),0)) | O36: =IF(OR(NOT(ISNUMBER(K36)),K36=0),"",ROUND(K36*(1+Settings!$C$7),0)) | P36: accessory
A37: E2. DB incline curl | B37: 3 | C37: 10 | D37: WT 20 lb ea DB | N37: =IF(OR(NOT(ISNUMBER(K37)),K37=0),"",ROUND(K37*(1+Settings!$B$7),0)) | O37: =IF(OR(NOT(ISNUMBER(K37)),K37=0),"",ROUND(K37*(1+Settings!$C$7),0)) | P37: accessory
A38: F. Side plank + reach-through | B38: 3 | C38: 8 ea side | D38: BW | M38: Anti-lateral flex + T-rotation. | N38: - | O38: - | P38: core
A41: COOL DOWN (5 min)
A42: Drill | H42: Dose | K42: Purpose
A43: Child's pose with side reach | H43: 30 sec ea | K43: Lat stretch after pull volume
A44: Doorway pec stretch (low angle) | H44: 30 sec ea | K44: Anterior shoulder open
A45: Banded lat stretch (gripping rack) | H45: 30 sec ea side | K45: Lat + posterior shoulder

Sheet M2D4
A1: Month 2 - Day 4 (Lower Body + Conditioning)
A2: Loading guidance: Same as Day 2
A3: WARMUP (8-10 min)
A4: Block A - Activation / Mobility (3-4 min)
A5: Drill | H5: Dose | K5: Cue
A6: 90/90 breathing on back, feet on bench | H6: 5 breaths | K6: Full exhale, ribs down, posterior pelvic tilt
A7: Glute bridge with 2-sec hold | H7: 10 reps | K7: Glute activation, ribs down at top
A8: Mini-band monster walk (forward and back) | H8: 10 steps | K8: Glute med activation
A9: 90/90 hip switches | H9: 6 ea side | K9: Hip IR/ER - golf-specific
A10: Block B - Dynamic Sequence (5-6 min, ~15-20 yd each, continuous flow)
A11: Movement | H11: Distance | K11: Focus
A12: Jog | H12: 20 yd down + back | K12: Easy aerobic primer
A13: Carioca | H13: 20 yd ea direction | K13: Hip rotation, frontal plane
A14: Walking lunge w/ rotation | H14: 8 reps | K14: Hip flexor + T-spine; PFP-aware depth
A15: Walking single-leg RDL | H15: 6 ea leg | K15: Posterior chain, balance
A16: Straight-leg kicks | H16: 8 ea leg | K16: Dynamic hamstring length
A17: Lateral lunges | H17: 6 ea side | K17: Adductor / frontal plane hip
A18: Side shuffles | H18: 15 yd ea x 2 | K18: Hip abductors, rotational prep
A19: Quick feet (ladder) | H19: 15-20 sec x 2 | K19: CNS prime, foot speed
A21: POWER PREP (~2 min)
A22: No explosive movements today - skip prep, proceed to Main Workout.
A28: MAIN WORKOUT
A29: Exercise | B29: Sets | C29: Reps | D29: Prescribed | E29: Wk 5 | G29: Wk 6 | I29: Wk 7 | K29: Wk 8 | M29: Notes | N29: Next-Cycle Target | P29: Category
E30: Load (lb) | F30: RPE | G30: Load (lb) | H30: RPE | I30: Load (lb) | J30: RPE | K30: Load (lb) | L30: RPE | N30: Min (lb) | O30: Max (lb)
A31: A. Hex bar Romanian deadlift | B31: 4 | C31: 8 | D31: WT 135 lb | M31: Volume hinge. Pause 1 sec at the knee on descent. RPE 7 target. | N31: =IF(OR(NOT(ISNUMBER(K31)),K31=0),"",ROUND(K31*(1+Settings!$B$6),0)) | O31: =IF(OR(NOT(ISNUMBER(K31)),K31=0),"",ROUND(K31*(1+Settings!$C$6),0)) | P31: compound
A32: B. Goblet box squat to 12" box | B32: 4 | C32: 10 | D32: WT 44 lb KB | M32: Box gives PFP-friendly depth. Sit back, don't drop. RPE 7. | N32: =IF(OR(NOT(ISNUMBER(K32)),K32=0),"",ROUND(K32*(1+Settings!$B$7),0)) | O32: =IF(OR(NOT(ISNUMBER(K32)),K32=0),"",ROUND(K32*(1+Settings!$C$7),0)) | P32: accessory
A33: C. Walking DB lunge (reverse if PFP flares) | B33: 3 | C33: 8 ea | D33: WT 30 lb ea DB | M33: Skip if knee symptoms. Sub step-ups. | N33: =IF(OR(NOT(ISNUMBER(K33)),K33=0),"",ROUND(K33*(1+Settings!$B$8),0)) | O33: =IF(OR(NOT(ISNUMBER(K33)),K33=0),"",ROUND(K33*(1+Settings!$C$8),0)) | P33: unilateral
A34: D. Single-leg hip thrust, shoulder on bench | B34: 3 | C34: 10 ea | D34: BW | M34: Glute med + max. Add 10-20 lb DB on hip when BW is easy. | N34: - | O34: - | P34: unilateral
A35: E. Conditioning finisher (3 rounds) | B35: 3 | C35: circuit | D35: Bike or stairs | M35: Bike 40s hard/20s easy x4, 60s rest. Or Stair climber 90s mod x3. Track avg watts. | N35: - | O35: - | P35: conditioning
A36: F. Standing cable wood chop (high-to-low) | B36: 3 | C36: 8 ea side | D36: WT 30 lb cable | M36: Golf-specific. Hips lead. | N36: =IF(OR(NOT(ISNUMBER(K36)),K36=0),"",ROUND(K36*(1+Settings!$B$11),0)) | O36: =IF(OR(NOT(ISNUMBER(K36)),K36=0),"",ROUND(K36*(1+Settings!$C$11),0)) | P36: core
A39: COOL DOWN (5 min)
A40: Drill | H40: Dose | K40: Purpose
A41: Nasal diaphragmatic breathing, supine | H41: 2 min | K41: HR down after conditioning
A42: Couch stretch | H42: 45 sec ea side | K42: Hip flexor recovery
A43: 90/90 hip stretch | H43: 45 sec ea | K43: Hip rotation

Sheet M3D1
A1: Month 3 - Day 1 (Conditioning Emphasis - mirrors M1D1)
A2: Loading guidance: Wk9: RPE 7 | Wk10: top single/double RPE 8 | Wk11: peak vol, RPE 8.5 | Wk12: hold, push reps - TEST | Progression pulled from: M1D1
A3: WARMUP (8-10 min)
A4: Block A - Activation / Mobility (3-4 min)
A5: Drill | H5: Dose | K5: Cue
A6: 90/90 breathing on back, feet on bench | H6: 5 breaths | K6: Full exhale, ribs down, posterior pelvic tilt
A7: 90/90 hip switches | H7: 6 ea side | K7: Hip IR/ER - golf-specific
A8: Open book / thoracic windmill (side-lying) | H8: 6 ea | K8: T-rotation + R shoulder ER - golf critical
A9: Yoga push-up / down-dog flow | H9: 5 reps | K9: T-spine + posterior chain wake-up
A10: Block B - Dynamic Sequence (5-6 min, ~15-20 yd each, continuous flow)
A11: Movement | H11: Distance | K11: Focus
A12: Jog | H12: 20 yd down + back | K12: Easy aerobic primer
A13: Carioca | H13: 20 yd ea direction | K13: Hip rotation, frontal plane
A14: Walking lunge w/ rotation | H14: 8 reps | K14: Hip flexor + T-spine; PFP-aware depth
A15: Walking single-leg RDL | H15: 6 ea leg | K15: Posterior chain, balance
A16: Straight-leg kicks | H16: 8 ea leg | K16: Dynamic hamstring length
A17: Lateral lunges | H17: 6 ea side | K17: Adductor / frontal plane hip
A18: Side shuffles | H18: 15 yd ea x 2 | K18: Hip abductors, rotational prep
A19: Quick feet (ladder) | H19: 15-20 sec x 2 | K19: CNS prime, foot speed
A21: POWER PREP (~2 min)
A22: Same-pattern prep (M3) | Pairs with: A. Med ball rotational throw - heavy
A23: Prep Movement | H23: Dose | K23: Cue
A24: Cable wood chop, slow w/ end-range pause | H24: 1 x 6 ea side | K24: Tempo 3-1-1, pause 2 sec at finish. Heavier tissue prep than M1.
A28: MAIN WORKOUT
A29: Exercise | B29: Sets | C29: Reps | D29: Prescribed | E29: Wk 9 | G29: Wk 10 | I29: Wk 11 | K29: Wk 12 | M29: Notes | N29: Next-Cycle Target | P29: Category
E30: Load (lb) | F30: RPE | G30: Load (lb) | H30: RPE | I30: Load (lb) | J30: RPE | K30: Load (lb) | L30: RPE | N30: Min (lb) | O30: Max (lb)
A31: A. Med ball rotational throw - heavy | B31: 4 | C31: 5 ea | D31: WT 14 lb | M31: Heavier balls now. Hips and ground drive. Progress to 20 lb by Wk 11 if velocity stays high. | N31: =IF(OR(NOT(ISNUMBER(K31)),K31=0),"",ROUND(K31*(1+Settings!$B$9),0)) | O31: =IF(OR(NOT(ISNUMBER(K31)),K31=0),"",ROUND(K31*(1+Settings!$C$9),0)) | P31: power
A32: B. Hex bar deadlift | B32: 4 | C32: 5 | D32: Pull from M1D2 | M32: Primer - not max effort. Conditioning day. Use 85-90% of M1D2 Wk4 actual. See Suggested Loads block. | N32: =IF(OR(NOT(ISNUMBER(K32)),K32=0),"",ROUND(K32*(1+Settings!$B$6),0)) | O32: =IF(OR(NOT(ISNUMBER(K32)),K32=0),"",ROUND(K32*(1+Settings!$C$6),0)) | P32: compound
A33: C1. KB front-rack reverse lunge | B33: 3 | C33: 8 ea | D33: WT 34 lb ea KB | M33: Pre-fatigue lower. Up from M1D4 26 lb. | N33: =IF(OR(NOT(ISNUMBER(K33)),K33=0),"",ROUND(K33*(1+Settings!$B$8),0)) | O33: =IF(OR(NOT(ISNUMBER(K33)),K33=0),"",ROUND(K33*(1+Settings!$C$8),0)) | P33: unilateral
A34: C2. 1-arm KB push press (light) | B34: 3 | C34: 6 ea | D34: WT 26 lb KB | M34: Optional - skip if R shoulder ROM limits. Sub standing barbell landmine press. | N34: =IF(OR(NOT(ISNUMBER(K34)),K34=0),"",ROUND(K34*(1+Settings!$B$7),0)) | O34: =IF(OR(NOT(ISNUMBER(K34)),K34=0),"",ROUND(K34*(1+Settings!$C$7),0)) | P34: accessory
A35: D. Conditioning circuit (4 rounds, 45s rest) | B35: 4 | C35: circuit | D35: KB swing 53 lb | M35: Bike 30s hard / KB swing x15 (53 lb) / hurdle side shuffle x2 / TRX row x10. | N35: - | O35: - | P35: conditioning
A36: E. Tall-kneeling anti-rotation chop | B36: 3 | C36: 8 ea side | D36: WT 30 lb cable | M36: Golf rotational primer. | N36: =IF(OR(NOT(ISNUMBER(K36)),K36=0),"",ROUND(K36*(1+Settings!$B$11),0)) | O36: =IF(OR(NOT(ISNUMBER(K36)),K36=0),"",ROUND(K36*(1+Settings!$C$11),0)) | P36: core
A39: COOL DOWN (5 min)
A40: Drill | H40: Dose | K40: Purpose
A41: Nasal diaphragmatic breathing, supine | H41: 2 min | K41: Down-regulate
A42: Half-kneeling adductor rock-back | H42: 8 reps ea | K42: Hip recovery
A43: Open book stretch hold | H43: 3 ea side | K43: T-spine + R shoulder
A45: Suggested Starting Loads (pulled from M1D1 Wk-end actuals)
A46: Exercise (this cycle) | B46: Prior cycle exercise (M1D1) | C46: Prior actual (last wk) | D46: Suggested Min | E46: Suggested Max
A47: A. Med ball rotational throw - heavy | B47: A1. Med ball rotational throw into wall | C47: =IF(ISNUMBER(M1D1!K31),M1D1!K31,"") | D47: =IF(OR(NOT(ISNUMBER(M1D1!K31)),M1D1!K31=0),"",ROUND(M1D1!K31*(1+Settings!$B$9),0)) | E47: =IF(OR(NOT(ISNUMBER(M1D1!K31)),M1D1!K31=0),"",ROUND(M1D1!K31*(1+Settings!$C$9),0))
...

Sheet M3D2
A1: Month 3 - Day 2 (Strength Emphasis - mirrors M1D2)
A2: Loading guidance: Same as M3D1 | Progression pulled from: M1D2
A3: WARMUP (8-10 min)
A4: Block A - Activation / Mobility (3-4 min)
A5: Drill | H5: Dose | K5: Cue
A6: 90/90 breathing on back, feet on bench | H6: 5 breaths | K6: Full exhale, ribs down, posterior pelvic tilt
A7: Glute bridge with 2-sec hold | H7: 10 reps | K7: Glute activation, ribs down at top
A8: Ankle rocks against wall | H8: 8 ea | K8: Dorsiflexion for PFP + squat patterning
A9: Bird dog with elbow-to-knee | H9: 6 ea | K9: Anti-extension + anti-rotation
A10: Block B - Dynamic Sequence (5-6 min, ~15-20 yd each, continuous flow)
A11: Movement | H11: Distance | K11: Focus
A12: Jog | H12: 20 yd down + back | K12: Easy aerobic primer
A13: Carioca | H13: 20 yd ea direction | K13: Hip rotation, frontal plane
A14: Walking lunge w/ rotation | H14: 8 reps | K14: Hip flexor + T-spine; PFP-aware depth
A15: Walking single-leg RDL | H15: 6 ea leg | K15: Posterior chain, balance
A16: Straight-leg kicks | H16: 8 ea leg | K16: Dynamic hamstring length
A17: Lateral lunges | H17: 6 ea side | K17: Adductor / frontal plane hip
A18: Side shuffles | H18: 15 yd ea x 2 | K18: Hip abductors, rotational prep
A19: Quick feet (ladder) | H19: 15-20 sec x 2 | K19: CNS prime, foot speed
A21: POWER PREP (~2 min)
A22: No explosive movements today - skip prep, proceed to Main Workout.
A28: MAIN WORKOUT
A29: Exercise | B29: Sets | C29: Reps | D29: Prescribed | E29: Wk 9 | G29: Wk 10 | I29: Wk 11 | K29: Wk 12 | M29: Notes | N29: Next-Cycle Target | P29: Category
E30: Load (lb) | F30: RPE | G30: Load (lb) | H30: RPE | I30: Load (lb) | J30: RPE | K30: Load (lb) | L30: RPE | N30: Min (lb) | O30: Max (lb)
A31: A. Hex bar deadlift | B31: 5 | C31: 5, 3, 3, 2, 2 | D31: Pull from M1D2 | M31: Peak strength sets to date. Target = M1D2 Wk4 +5-10%. See Suggested Loads block. RPE 8 top sets. | N31: =IF(OR(NOT(ISNUMBER(K31)),K31=0),"",ROUND(K31*(1+Settings!$B$6),0)) | O31: =IF(OR(NOT(ISNUMBER(K31)),K31=0),"",ROUND(K31*(1+Settings!$C$6),0)) | P31: compound
A32: B. DB bench press | B32: 4 | C32: 6 | D32: Pull from M1D2 | M32: If R shoulder good, push load. Target = M1D2 floor press Wk4 +5-10%. RPE 8. | N32: =IF(OR(NOT(ISNUMBER(K32)),K32=0),"",ROUND(K32*(1+Settings!$B$6),0)) | O32: =IF(OR(NOT(ISNUMBER(K32)),K32=0),"",ROUND(K32*(1+Settings!$C$6),0)) | P32: compound
A33: C. Bulgarian split squat | B33: 4 | C33: 6 ea | D33: Pull from M1D2 | M33: Heaviest split squat to date. Target = M1D2 Wk4 +7-15%. RPE 8. | N33: =IF(OR(NOT(ISNUMBER(K33)),K33=0),"",ROUND(K33*(1+Settings!$B$8),0)) | O33: =IF(OR(NOT(ISNUMBER(K33)),K33=0),"",ROUND(K33*(1+Settings!$C$8),0)) | P33: unilateral
A34: D. Weighted pull-up or heaviest pulldown | B34: 3 | C34: 6 | D34: WT 110 lb pulldown | M34: Neutral grip if available. RPE 8 target. Or +10-15 lb on pull-up if doing weighted. | N34: =IF(OR(NOT(ISNUMBER(K34)),K34=0),"",ROUND(K34*(1+Settings!$B$6),0)) | O34: =IF(OR(NOT(ISNUMBER(K34)),K34=0),"",ROUND(K34*(1+Settings!$C$6),0)) | P34: compound
A35: E. Glute-ham Nordic eccentric (slower) | B35: 3 | C35: 5 | D35: BW, 5-6 sec descent | M35: Build hamstring strength. Progression = slower eccentric, not load. | N35: - | O35: - | P35: accessory
A36: F. Hollow body hold or dead bug | B36: 3 | C36: 30-40 sec | D36: BW + 4 lb ankles | M36: Anti-extension. Use 4 lb ankle weights for dead bug variation. | N36: - | O36: - | P36: core
A39: COOL DOWN (5 min)
A40: Drill | H40: Dose | K40: Purpose
A41: Couch stretch | H41: 45 sec ea side | K41: Hip flexor recovery after heavy lower
A42: Doorway pec stretch at 90/90 | H42: 30 sec ea | K42: Counter pressing
A43: Foam roll T-spine extensions | H43: 8 reps | K43: Posture reset
A45: Suggested Starting Loads (pulled from M1D2 Wk-end actuals)
A46: Exercise (this cycle) | B46: Prior cycle exercise (M1D2) | C46: Prior actual (last wk) | D46: Suggested Min | E46: Suggested Max
A47: A. Hex bar deadlift | B47: A. Hex bar deadlift | C47: =IF(ISNUMBER(M1D2!K31),M1D2!K31,"") | D47: =IF(OR(NOT(ISNUMBER(M1D2!K31)),M1D2!K31=0),"",ROUND(M1D2!K31*(1+Settings!$B$6),0)) | E47: =IF(OR(NOT(ISNUMBER(M1D2!K31)),M1D2!K31=0),"",ROUND(M1D2!K31*(1+Settings!$C$6),0))
A48: B. DB bench press | B48: B1. DB floor press (neutral grip) | C48: =IF(ISNUMBER(M1D2!K32),M1D2!K32,"") | D48: =IF(OR(NOT(ISNUMBER(M1D2!K32)),M1D2!K32=0),"",ROUND(M1D2!K32*(1+Settings!$B$6),0)) | E48: =IF(OR(NOT(ISNUMBER(M1D2!K32)),M1D2!K32=0),"",ROUND(M1D2!K32*(1+Settings!$C$6),0))
A49: C. Bulgarian split squat | B49: C1. Bulgarian split squat | C49: =IF(ISNUMBER(M1D2!K34),M1D2!K34,"") | D49: =IF(OR(NOT(ISNUMBER(M1D2!K34)),M1D2!K34=0),"",ROUND(M1D2!K34*(1+Settings!$B$8),0)) | E49: =IF(OR(NOT(ISNUMBER(M1D2!K34)),M1D2!K34=0),"",ROUND(M1D2!K34*(1+Settings!$C$8),0))
...

Sheet M3D3
A1: Month 3 - Day 3 (Conditioning Emphasis - mirrors M1D3)
A2: Loading guidance: Same as M3D1 | Progression pulled from: M1D3
A3: WARMUP (8-10 min)
A4: Block A - Activation / Mobility (3-4 min)
A5: Drill | H5: Dose | K5: Cue
A6: 90/90 breathing on back, feet on bench | H6: 5 breaths | K6: Full exhale, ribs down, posterior pelvic tilt
A7: 90/90 hip switches | H7: 6 ea side | K7: Hip IR/ER - golf-specific
A8: Mini-band monster walk (forward and back) | H8: 10 steps | K8: Glute med activation
A9: Wall slides, palms forward | H9: 8 reps | K9: Scap upward rotation, no forced flexion
A10: Block B - Dynamic Sequence (5-6 min, ~15-20 yd each, continuous flow)
A11: Movement | H11: Distance | K11: Focus
A12: Jog | H12: 20 yd down + back | K12: Easy aerobic primer
A13: Carioca | H13: 20 yd ea direction | K13: Hip rotation, frontal plane
A14: Walking lunge w/ rotation | H14: 8 reps | K14: Hip flexor + T-spine; PFP-aware depth
A15: Walking single-leg RDL | H15: 6 ea leg | K15: Posterior chain, balance
A16: Straight-leg kicks | H16: 8 ea leg | K16: Dynamic hamstring length
A17: Lateral lunges | H17: 6 ea side | K17: Adductor / frontal plane hip
A18: Side shuffles | H18: 15 yd ea x 2 | K18: Hip abductors, rotational prep
A19: Quick feet (ladder) | H19: 15-20 sec x 2 | K19: CNS prime, foot speed
A21: POWER PREP (~2 min)
A22: Same-pattern prep (M3) | Pairs with: A1. MB scoop toss + A2. Box jump
A23: Prep Movement | H23: Dose | K23: Cue
A24: Cable wood chop low-to-high, slow | H24: 1 x 5 ea side | K24: Same plane as scoop toss. Tempo 3-1-1.
A25: Tempo goblet squat (3-1-1) | H25: 1 x 5 | K25: Same pattern as jump. Down 3 sec, pause 1, up 1 sec.
A28: MAIN WORKOUT
A29: Exercise | B29: Sets | C29: Reps | D29: Prescribed | E29: Wk 9 | G29: Wk 10 | I29: Wk 11 | K29: Wk 12 | M29: Notes | N29: Next-Cycle Target | P29: Category
E30: Load (lb) | F30: RPE | G30: Load (lb) | H30: RPE | I30: Load (lb) | J30: RPE | K30: Load (lb) | L30: RPE | N30: Min (lb) | O30: Max (lb)
A31: A1. Med ball scoop toss (rotational, sideways) | B31: 4 | C31: 5 ea side | D31: WT 14 lb | M31: Golf-specific power. | N31: =IF(OR(NOT(ISNUMBER(K31)),K31=0),"",ROUND(K31*(1+Settings!$B$9),0)) | O31: =IF(OR(NOT(ISNUMBER(K31)),K31=0),"",ROUND(K31*(1+Settings!$C$9),0)) | P31: power
A32: A2. Box jump 12-20" (step down) | B32: 4 | C32: 5 | D32: BW | M32: Step down to protect knees and back. Sub broad jump if PFP. Wk 9 = 12", Wk 11+ = 20". | N32: - | O32: - | P32: power
A33: B1. Goblet squat to 12" box | B33: 3 | C33: 10 | D33: WT 44 lb KB | M33: Up from M1D3 34 lb. | N33: =IF(OR(NOT(ISNUMBER(K33)),K33=0),"",ROUND(K33*(1+Settings!$B$7),0)) | O33: =IF(OR(NOT(ISNUMBER(K33)),K33=0),"",ROUND(K33*(1+Settings!$C$7),0)) | P33: accessory
A34: B2. Standing 1-arm cable row | B34: 3 | C34: 10 ea | D34: WT 50 lb cable | M34: Anti-rotation. Up from M1D3 30 lb. | N34: =IF(OR(NOT(ISNUMBER(K34)),K34=0),"",ROUND(K34*(1+Settings!$B$7),0)) | O34: =IF(OR(NOT(ISNUMBER(K34)),K34=0),"",ROUND(K34*(1+Settings!$C$7),0)) | P34: accessory
A35: C. Intervals - Stair climber | B35: 1 | C35: 8 x 60s mod-hard/60s easy | D35: Track level | M35: Add 1 round each week up to Wk 11. Log avg level/step rate. | N35: - | O35: - | P35: conditioning
A36: D. Ankle weight side-lying leg lifts | B36: 3 | C36: 12 ea | D36: WT 4 lb ankle | M36: Hip stability for golf and PFP. Progress to 6 lb by Wk 11. | N36: =IF(OR(NOT(ISNUMBER(K36)),K36=0),"",ROUND(K36*(1+Settings!$B$7),0)) | O36: =IF(OR(NOT(ISNUMBER(K36)),K36=0),"",ROUND(K36*(1+Settings!$C$7),0)) | P36: accessory
A37: E. Single-leg balance with reach (airex) | B37: 3 | C37: 8 ea | D37: BW | M37: Reactive single-leg stability. | N37: - | O37: - | P37: core
A40: COOL DOWN (5 min)
A41: Drill | H41: Dose | K41: Purpose
A42: Nasal diaphragmatic breathing, supine | H42: 2 min | K42: HR down
A43: Standing forward fold, soft knees | H43: 45 sec | K43: Posterior chain
A44: Child's pose with side reach | H44: 30 sec ea | K44: Lat + T-spine
A46: Suggested Starting Loads (pulled from M1D3 Wk-end actuals)
...

Sheet M3D4
A1: Month 3 - Day 4 (Strength Emphasis - mirrors M1D4)
A2: Loading guidance: Same as M3D1 | Progression pulled from: M1D4
A3: WARMUP (8-10 min)
A4: Block A - Activation / Mobility (3-4 min)
A5: Drill | H5: Dose | K5: Cue
A6: 90/90 breathing on back, feet on bench | H6: 5 breaths | K6: Full exhale, ribs down, posterior pelvic tilt
A7: Open book / thoracic windmill (side-lying) | H7: 6 ea | K7: T-rotation + R shoulder ER - golf critical
A8: Standing band shoulder ER at 0 deg abd | H8: 10 ea | K8: Cuff activation - critical for R shoulder
A9: World's greatest stretch (slow) | H9: 4 ea side | K9: Hip flexor, T-spine, hamstring
A10: Block B - Dynamic Sequence (5-6 min, ~15-20 yd each, continuous flow)
A11: Movement | H11: Distance | K11: Focus
A12: Jog | H12: 20 yd down + back | K12: Easy aerobic primer
A13: Carioca | H13: 20 yd ea direction | K13: Hip rotation, frontal plane
A14: Walking lunge w/ rotation | H14: 8 reps | K14: Hip flexor + T-spine; PFP-aware depth
A15: Walking single-leg RDL | H15: 6 ea leg | K15: Posterior chain, balance
A16: Straight-leg kicks | H16: 8 ea leg | K16: Dynamic hamstring length
A17: Lateral lunges | H17: 6 ea side | K17: Adductor / frontal plane hip
A18: Side shuffles | H18: 15 yd ea x 2 | K18: Hip abductors, rotational prep
A19: Quick feet (ladder) | H19: 15-20 sec x 2 | K19: CNS prime, foot speed
A21: POWER PREP (~2 min)
A22: No explosive movements today - skip prep, proceed to Main Workout.
A28: MAIN WORKOUT
A29: Exercise | B29: Sets | C29: Reps | D29: Prescribed | E29: Wk 9 | G29: Wk 10 | I29: Wk 11 | K29: Wk 12 | M29: Notes | N29: Next-Cycle Target | P29: Category
E30: Load (lb) | F30: RPE | G30: Load (lb) | H30: RPE | I30: Load (lb) | J30: RPE | K30: Load (lb) | L30: RPE | N30: Min (lb) | O30: Max (lb)
A31: A. Hex bar RDL | B31: 4 | C31: 5 | D31: Pull from M1D4 | M31: Heaviest hinge sets. Target = M1D4 Wk4 +5-10%. RPE 8. | N31: =IF(OR(NOT(ISNUMBER(K31)),K31=0),"",ROUND(K31*(1+Settings!$B$6),0)) | O31: =IF(OR(NOT(ISNUMBER(K31)),K31=0),"",ROUND(K31*(1+Settings!$C$6),0)) | P31: compound
A32: B. DB incline press, neutral grip | B32: 4 | C32: 8 | D32: WT 40 lb ea DB | M32: Up from M1D4 half-kneeling press 25 lb. RPE 8 target. | N32: =IF(OR(NOT(ISNUMBER(K32)),K32=0),"",ROUND(K32*(1+Settings!$B$7),0)) | O32: =IF(OR(NOT(ISNUMBER(K32)),K32=0),"",ROUND(K32*(1+Settings!$C$7),0)) | P32: accessory
A33: C. Chest-supported DB row | B33: 4 | C33: 8 | D33: Pull from M1D4 | M33: Heavy. Pause at top. Target = M1D4 Wk4 +7-12.5%. RPE 8. | N33: =IF(OR(NOT(ISNUMBER(K33)),K33=0),"",ROUND(K33*(1+Settings!$B$7),0)) | O33: =IF(OR(NOT(ISNUMBER(K33)),K33=0),"",ROUND(K33*(1+Settings!$C$7),0)) | P33: accessory
A34: D1. Step-up to 20" box (alternating) | B34: 3 | C34: 6 ea | D34: WT 35 lb ea DB | M34: Drive through top heel. Up from M1D3 step-up 25 lb (taller box now). | N34: =IF(OR(NOT(ISNUMBER(K34)),K34=0),"",ROUND(K34*(1+Settings!$B$8),0)) | O34: =IF(OR(NOT(ISNUMBER(K34)),K34=0),"",ROUND(K34*(1+Settings!$C$8),0)) | P34: unilateral
A35: D2. 1-arm KB farmer carry | B35: 3 | C35: 40 yd ea | D35: WT 62 lb KB | M35: Suitcase position. No lean. Up from M1D2 53 lb. Progress to 70-80 lb if controlled. | N35: =IF(OR(NOT(ISNUMBER(K35)),K35=0),"",ROUND(K35*(1+Settings!$B$8),0)) | O35: =IF(OR(NOT(ISNUMBER(K35)),K35=0),"",ROUND(K35*(1+Settings!$C$8),0)) | P35: unilateral
A36: E. Cable wood chop (both directions) | B36: 3 | C36: 8 ea direction | D36: WT 30 lb cable | M36: Both planes of rotational power. | N36: =IF(OR(NOT(ISNUMBER(K36)),K36=0),"",ROUND(K36*(1+Settings!$B$11),0)) | O36: =IF(OR(NOT(ISNUMBER(K36)),K36=0),"",ROUND(K36*(1+Settings!$C$11),0)) | P36: core
A39: COOL DOWN (5 min)
A40: Drill | H40: Dose | K40: Purpose
A41: Couch stretch | H41: 45 sec ea side | K41: Hip flexor recovery
A42: Open book stretch hold | H42: 3 ea side | K42: R shoulder ER + T-spine
A43: Standing forward fold | H43: 45 sec | K43: Posterior chain
A45: Suggested Starting Loads (pulled from M1D4 Wk-end actuals)
A46: Exercise (this cycle) | B46: Prior cycle exercise (M1D4) | C46: Prior actual (last wk) | D46: Suggested Min | E46: Suggested Max
A47: A. Hex bar RDL | B47: A. Hex bar Romanian deadlift | C47: =IF(ISNUMBER(M1D4!K31),M1D4!K31,"") | D47: =IF(OR(NOT(ISNUMBER(M1D4!K31)),M1D4!K31=0),"",ROUND(M1D4!K31*(1+Settings!$B$6),0)) | E47: =IF(OR(NOT(ISNUMBER(M1D4!K31)),M1D4!K31=0),"",ROUND(M1D4!K31*(1+Settings!$C$6),0))
A48: B. DB incline press, neutral grip | B48: B1. Half-kneeling 1-arm DB press (neutral) | C48: =IF(ISNUMBER(M1D4!K32),M1D4!K32,"") | D48: =IF(OR(NOT(ISNUMBER(M1D4!K32)),M1D4!K32=0),"",ROUND(M1D4!K32*(1+Settings!$B$7),0)) | E48: =IF(OR(NOT(ISNUMBER(M1D4!K32)),M1D4!K32=0),"",ROUND(M1D4!K32*(1+Settings!$C$7),0))
A49: C. Chest-supported DB row | B49: B2. Chest-supported DB row | C49: =IF(ISNUMBER(M1D4!K33),M1D4!K33,"") | D49: =IF(OR(NOT(ISNUMBER(M1D4!K33)),M1D4!K33=0),"",ROUND(M1D4!K33*(1+Settings!$B$7),0)) | E49: =IF(OR(NOT(ISNUMBER(M1D4!K33)),M1D4!K33=0),"",ROUND(M1D4!K33*(1+Settings!$C$7),0))
...

Sheet M4D1
A1: Month 4 - Day 1 (Push - mirrors M2D1)
A2: Loading guidance: Wk13: RPE 7-8 | Wk14: RPE 8, top single | Wk15: RPE 8.5 peak | Wk16: DELOAD + retest | Progression pulled from: M2D1
A3: WARMUP (8-10 min)
A4: Block A - Activation / Mobility (3-4 min)
A5: Drill | H5: Dose | K5: Cue
A6: 90/90 breathing on back, feet on bench | H6: 5 breaths | K6: Full exhale, ribs down, posterior pelvic tilt
A7: Standing band shoulder ER at 0 deg abd | H7: 10 ea | K7: Cuff activation - critical for R shoulder
A8: Wall slides, palms forward | H8: 8 reps | K8: Scap upward rotation, no forced flexion
A9: Scapular push-up | H9: 8 reps | K9: Protraction/retraction without elbow bend
A10: Block B - Dynamic Sequence (5-6 min, ~15-20 yd each, continuous flow)
A11: Movement | H11: Distance | K11: Focus
A12: Jog | H12: 20 yd down + back | K12: Easy aerobic primer
A13: Carioca | H13: 20 yd ea direction | K13: Hip rotation, frontal plane
A14: Walking lunge w/ rotation | H14: 8 reps | K14: Hip flexor + T-spine; PFP-aware depth
A15: Walking single-leg RDL | H15: 6 ea leg | K15: Posterior chain, balance
A16: Straight-leg kicks | H16: 8 ea leg | K16: Dynamic hamstring length
A17: Lateral lunges | H17: 6 ea side | K17: Adductor / frontal plane hip
A18: Side shuffles | H18: 15 yd ea x 2 | K18: Hip abductors, rotational prep
A19: Quick feet (ladder) | H19: 15-20 sec x 2 | K19: CNS prime, foot speed
A21: POWER PREP (~2 min)
A22: No explosive movements today - skip prep, proceed to Main Workout.
A28: MAIN WORKOUT
A29: Exercise | B29: Sets | C29: Reps | D29: Prescribed | E29: Wk 13 | G29: Wk 14 | I29: Wk 15 | K29: Wk 16 | M29: Notes | N29: Next-Cycle Target | P29: Category
E30: Load (lb) | F30: RPE | G30: Load (lb) | H30: RPE | I30: Load (lb) | J30: RPE | K30: Load (lb) | L30: RPE | N30: Min (lb) | O30: Max (lb)
A31: A. DB bench press (neutral if needed) | B31: 5 | C31: 5, 5, 3, 3, 3 | D31: Pull from M2D1 | M31: Strongest pressing of the program. Target = M2D1 Wk7 +5-10%. RPE 8. | N31: =IF(OR(NOT(ISNUMBER(K31)),K31=0),"",ROUND(K31*(1+Settings!$B$6),0)) | O31: =IF(OR(NOT(ISNUMBER(K31)),K31=0),"",ROUND(K31*(1+Settings!$C$6),0)) | P31: compound
A32: B. Standing barbell landmine press (1-arm) | B32: 4 | C32: 8 ea | D32: Pull from M2D1 | M32: Barbell in landmine, plates on working end. Target = M2D1 Wk7 +7-12.5%. Best overhead sub for R TSA. | N32: =IF(OR(NOT(ISNUMBER(K32)),K32=0),"",ROUND(K32*(1+Settings!$B$7),0)) | O32: =IF(OR(NOT(ISNUMBER(K32)),K32=0),"",ROUND(K32*(1+Settings!$C$7),0)) | P32: accessory
A33: C. Low-incline DB press (~15 deg) | B33: 3 | C33: 10 | D33: WT 40 lb ea DB | M33: RPE 8 target. Slight incline keeps R shoulder happy vs flat. | N33: =IF(OR(NOT(ISNUMBER(K33)),K33=0),"",ROUND(K33*(1+Settings!$B$7),0)) | O33: =IF(OR(NOT(ISNUMBER(K33)),K33=0),"",ROUND(K33*(1+Settings!$C$7),0)) | P33: accessory
A34: D1. Cable lateral raise (light, partial ROM) | B34: 3 | C34: 12 ea | D34: WT 10 lb cable | M34: Bias mid-range, avoid forced end-range. Strict tempo. | N34: =IF(OR(NOT(ISNUMBER(K34)),K34=0),"",ROUND(K34*(1+Settings!$B$7),0)) | O34: =IF(OR(NOT(ISNUMBER(K34)),K34=0),"",ROUND(K34*(1+Settings!$C$7),0)) | P34: accessory
A35: D2. Cable triceps push-down | B35: 3 | C35: 12 | D35: WT 50 lb cable | N35: =IF(OR(NOT(ISNUMBER(K35)),K35=0),"",ROUND(K35*(1+Settings!$B$7),0)) | O35: =IF(OR(NOT(ISNUMBER(K35)),K35=0),"",ROUND(K35*(1+Settings!$C$7),0)) | P35: accessory
A36: E. TRX face pull + ER | B36: 3 | C36: 12 | D36: BW (foot angle) | M36: Cuff insurance, every push day. | N36: - | O36: - | P36: accessory
A37: F. TRX fallout or plank shoulder tap | B37: 3 | C37: 8 | D37: BW | M37: Plank tap if R shoulder limits fallout. | N37: - | O37: - | P37: core
A40: COOL DOWN (5 min)
A41: Drill | H41: Dose | K41: Purpose
A42: Doorway pec stretch at 90/90 | H42: 30 sec ea | K42: Counter heavy pressing
A43: Banded shoulder distraction | H43: 30 sec ea | K43: Decompress R shoulder
A44: Child's pose with side reach | H44: 30 sec ea | K44: Lat + T-spine
A46: Suggested Starting Loads (pulled from M2D1 Wk-end actuals)
A47: Exercise (this cycle) | B47: Prior cycle exercise (M2D1) | C47: Prior actual (last wk) | D47: Suggested Min | E47: Suggested Max
A48: A. DB bench press (neutral if needed) | B48: B. DB floor press or bench press | C48: =IF(ISNUMBER(M2D1!K32),M2D1!K32,"") | D48: =IF(OR(NOT(ISNUMBER(M2D1!K32)),M2D1!K32=0),"",ROUND(M2D1!K32*(1+Settings!$B$6),0)) | E48: =IF(OR(NOT(ISNUMBER(M2D1!K32)),M2D1!K32=0),"",ROUND(M2D1!K32*(1+Settings!$C$6),0))
A49: B. Standing barbell landmine press (1-arm) | B49: C. Standing barbell landmine press (1-arm) | C49: =IF(ISNUMBER(M2D1!K33),M2D1!K33,"") | D49: =IF(OR(NOT(ISNUMBER(M2D1!K33)),M2D1!K33=0),"",ROUND(M2D1!K33*(1+Settings!$B$7),0)) | E49: =IF(OR(NOT(ISNUMBER(M2D1!K33)),M2D1!K33=0),"",ROUND(M2D1!K33*(1+Settings!$C$7),0))
...

Sheet M4D2
A1: Month 4 - Day 2 (Pull + Trunk - mirrors M2D3)
A2: Loading guidance: Same as M4D1 | Progression pulled from: M2D3
A3: WARMUP (8-10 min)
A4: Block A - Activation / Mobility (3-4 min)
A5: Drill | H5: Dose | K5: Cue
A6: 90/90 breathing on back, feet on bench | H6: 5 breaths | K6: Full exhale, ribs down, posterior pelvic tilt
A7: Scapular push-up | H7: 8 reps | K7: Protraction/retraction without elbow bend
A8: Open book / thoracic windmill (side-lying) | H8: 6 ea | K8: T-rotation + R shoulder ER - golf critical
A9: Wall slides, palms forward | H9: 8 reps | K9: Scap upward rotation, no forced flexion
A10: Block B - Dynamic Sequence (5-6 min, ~15-20 yd each, continuous flow)
A11: Movement | H11: Distance | K11: Focus
A12: Jog | H12: 20 yd down + back | K12: Easy aerobic primer
A13: Carioca | H13: 20 yd ea direction | K13: Hip rotation, frontal plane
A14: Walking lunge w/ rotation | H14: 8 reps | K14: Hip flexor + T-spine; PFP-aware depth
A15: Walking single-leg RDL | H15: 6 ea leg | K15: Posterior chain, balance
A16: Straight-leg kicks | H16: 8 ea leg | K16: Dynamic hamstring length
A17: Lateral lunges | H17: 6 ea side | K17: Adductor / frontal plane hip
A18: Side shuffles | H18: 15 yd ea x 2 | K18: Hip abductors, rotational prep
A19: Quick feet (ladder) | H19: 15-20 sec x 2 | K19: CNS prime, foot speed
A21: POWER PREP (~2 min)
A22: No explosive movements today - skip prep, proceed to Main Workout.
A28: MAIN WORKOUT
A29: Exercise | B29: Sets | C29: Reps | D29: Prescribed | E29: Wk 13 | G29: Wk 14 | I29: Wk 15 | K29: Wk 16 | M29: Notes | N29: Next-Cycle Target | P29: Category
E30: Load (lb) | F30: RPE | G30: Load (lb) | H30: RPE | I30: Load (lb) | J30: RPE | K30: Load (lb) | L30: RPE | N30: Min (lb) | O30: Max (lb)
A31: A. Pull-up (weighted if able) or pulldown | B31: 5 | C31: 6, 6, 5, 5, 5 | D31: Pull from M2D3 | M31: No kipping. Slow eccentric. Target = M2D3 Wk7 +5-10%. RPE 8. | N31: =IF(OR(NOT(ISNUMBER(K31)),K31=0),"",ROUND(K31*(1+Settings!$B$6),0)) | O31: =IF(OR(NOT(ISNUMBER(K31)),K31=0),"",ROUND(K31*(1+Settings!$C$6),0)) | P31: compound
A32: B. 1-arm DB row, bench-supported | B32: 4 | C32: 8 ea | D32: Pull from M2D3 | M32: Heaviest rows of the program. Target = M2D3 Wk7 +7-12.5%. RPE 8. | N32: =IF(OR(NOT(ISNUMBER(K32)),K32=0),"",ROUND(K32*(1+Settings!$B$7),0)) | O32: =IF(OR(NOT(ISNUMBER(K32)),K32=0),"",ROUND(K32*(1+Settings!$C$7),0)) | P32: accessory
A33: C. Chest-supported DB row | B33: 3 | C33: 10 | D33: Pull from M2D1 | M33: Volume row variation. Target = M2D1 Wk7 +7-12.5%. | N33: =IF(OR(NOT(ISNUMBER(K33)),K33=0),"",ROUND(K33*(1+Settings!$B$7),0)) | O33: =IF(OR(NOT(ISNUMBER(K33)),K33=0),"",ROUND(K33*(1+Settings!$C$7),0)) | P33: accessory
A34: D1. Cable face pull + ER | B34: 3 | C34: 12 | D34: WT 40 lb cable | M34: Up from M2D3 30 lb. | N34: =IF(OR(NOT(ISNUMBER(K34)),K34=0),"",ROUND(K34*(1+Settings!$B$7),0)) | O34: =IF(OR(NOT(ISNUMBER(K34)),K34=0),"",ROUND(K34*(1+Settings!$C$7),0)) | P34: accessory
